Traceback (most recent call last):
  File "C:\Users\henni\anaconda3\envs\j_books\lib\site-packages\jupyter_cache\executors\utils.py", line 51, in single_nb_execution
    executenb(
  File "C:\Users\henni\anaconda3\envs\j_books\lib\site-packages\nbclient\client.py", line 1204, in execute
    return NotebookClient(nb=nb, resources=resources, km=km, **kwargs).execute()
  File "C:\Users\henni\anaconda3\envs\j_books\lib\site-packages\nbclient\util.py", line 84, in wrapped
    return just_run(coro(*args, **kwargs))
  File "C:\Users\henni\anaconda3\envs\j_books\lib\site-packages\nbclient\util.py", line 62, in just_run
    return loop.run_until_complete(coro)
  File "C:\Users\henni\anaconda3\envs\j_books\lib\asyncio\base_events.py", line 616, in run_until_complete
    return future.result()
  File "C:\Users\henni\anaconda3\envs\j_books\lib\site-packages\nbclient\client.py", line 663, in async_execute
    await self.async_execute_cell(
  File "C:\Users\henni\anaconda3\envs\j_books\lib\site-packages\nbclient\client.py", line 965, in async_execute_cell
    await self._check_raise_for_error(cell, cell_index, exec_reply)
  File "C:\Users\henni\anaconda3\envs\j_books\lib\site-packages\nbclient\client.py", line 862, in _check_raise_for_error
    raise CellExecutionError.from_cell_and_msg(cell, exec_reply_content)
nbclient.exceptions.CellExecutionError: An error occurred while executing the following cell:
------------------
#---------------------------------------
# SETUP

from airflow import DAG
from airflow.operators.bash import BashOperator
from datetime import datetime, timedelta

#---------------------------------------


# DEFAULT DAG ARGUMENTS

with DAG(
    'my_dag', 
    default_args={
        'depends_on_past': False,
        'email': ['my-email@example.com'],
        'email_on_failure': False,
        'email_on_retry': False,
        'retries': 1,
        'retry_delay': timedelta(minutes=5),
    },
    description='A simple DAG for Coin Model',
    schedule_interval= '@daily',
    start_date=datetime(2022, 6, 23),
    catchup=False,

) as dag:

    #---------------------------------------

    # DEFINE OPERATERS

    #BashOperator for image_to_file
    t1 = BashOperator(
        depends_on_past=False,
        task_id='image_to_file',
        bash_command="python '/Users/Kim/Library/Mobile Documents/com~apple~CloudDocs/UNI/HdM/Semester6/DataScience&MLOps/airflow/dags/image_to_file.py'",
    )

   #----------------

    # SETTING UP DEPENDENCIES
    t1
------------------

[1;31m---------------------------------------------------------------------------[0m
[1;31mModuleNotFoundError[0m                       Traceback (most recent call last)
Input [1;32mIn [1][0m, in [0;36m<cell line: 4>[1;34m()[0m
[0;32m      1[0m [38;5;66;03m#---------------------------------------[39;00m
[0;32m      2[0m [38;5;66;03m# SETUP[39;00m
[1;32m----> 4[0m [38;5;28;01mfrom[39;00m [38;5;21;01mairflow[39;00m [38;5;28;01mimport[39;00m DAG
[0;32m      5[0m [38;5;28;01mfrom[39;00m [38;5;21;01mairflow[39;00m[38;5;21;01m.[39;00m[38;5;21;01moperators[39;00m[38;5;21;01m.[39;00m[38;5;21;01mbash[39;00m [38;5;28;01mimport[39;00m BashOperator
[0;32m      6[0m [38;5;28;01mfrom[39;00m [38;5;21;01mdatetime[39;00m [38;5;28;01mimport[39;00m datetime, timedelta

[1;31mModuleNotFoundError[0m: No module named 'airflow'
ModuleNotFoundError: No module named 'airflow'

